
public class Exception_Hanlding {

	public static void main(String[] args) {
		
		try{  
		   int a[]=new int[5];  
		    a[5]=30/5;  
		    
		   }  
		   catch(ArithmeticException e){System.out.println("task1 is completed");}  
//		   catch(ArrayIndexOutOfBoundsException e){System.out.println("task 2 completed");}  
//		   catch(Exception e){System.out.println("common task completed");}  
		  System.out.println("Print me as well");
		   System.out.println("rest of the code...");  
		 }  

}
